<?xml version="1.0" ?>
<!-- =================================================================================== -->
<!-- |    This document was autogenerated by xacro from allegro_hand_description_right.xacro | -->
<!-- |    EDITING THIS FILE BY HAND IS NOT RECOMMENDED                                 | -->
<!-- =================================================================================== -->
<robot name="allegro_hand_right" xmlns:xacro="http://www.ros.org/wiki/xacro">
  <!--
rosrun xacro xacro.py allegro_hand_description_right.urdf.xacro > allegro_hand_description_right.urdf
roslaunch launchers/fuerte/allegro_hand_jgui_right_virtual.launch 
-->
  <!-- ======================== BASE PARAMS ========================= -->
  <!-- ======================== FINGER PARAMS ======================== -->
  <!-- full height from joint to tip. when used,
the radius of the finger tip sphere will be subtracted
and one fixed link will be added for the tip. -->
  <!--0.0435,   0.044981-->
  <!--0.002298-->
  <!--0.002298-->
  <!-- ========================= THUMB PARAMS ========================= -->
  <!-- ========================= LIMITS ========================= -->
  <!-- ============================================================================= -->
  <!-- ============================================================================= -->
  <!-- ============================================================================= -->
  <!-- BASE -->
  <link name="base_link">
    <visual>
      <geometry>
        <mesh filename="meshes/base_link.STL"/>
      </geometry>
      <!-- LEFT -->
      <!-- <origin rpy="${-90*DEG2RAD} 0 0" xyz="0 0 0 "/> -->
      <!-- RIGHT -->
      <origin rpy="0 0 0" xyz="0 0 0 "/>
      <material name="black">
        <color rgba="0.2 0.2 0.2 1"/>
      </material>
    </visual>
    <inertial>
      <mass value="0.41540000"/>
      <inertia ixx="2.3161e-7" ixy="-2.7805e-10" ixz="1.4202e-9" iyy="1.4231e-7" iyz="-8.8101e-9" izz="1.2820e-7"/>
      <origin xyz="-0.00952503 0.00046095 -0.03822657"/>
    </inertial>
    <collision>
      <origin rpy="0 0 0" xyz="-0.009300 0 -0.0475"/>
      <geometry>
        <box size="0.0408 0.1130 0.095"/>
      </geometry>
    </collision>
  </link>
  <!-- ============================================================================= -->
  <!-- FINGERS -->
  <!-- RIGHT HAND due to which finger is number 0 -->
  <!-- for LEFT HAND switch the sign of the **offset_origin_y** and **finger_angle_r** parameters-->
  <link name="link_0">
    <visual>
      <geometry>
        <mesh filename="meshes/link_0.0.STL"/>
      </geometry>
      <material name="black"/>
    </visual>
    <inertial>
      <mass value="0.01190000"/>
      <inertia ixx="4.3968e-10" ixy="4.8612e-13" ixz="1.6056e-11" iyy="2.1654e-10" iyz="-5.7592e-12" izz="4.2916e-10"/>
      <origin xyz="-0.00047307 0.00024005 0.00596328"/>
    </inertial>
    <collision>
      <geometry>
        <box size="0.0196 0.0275 0.0164"/>
      </geometry>
      <origin rpy="0 0 0" xyz="0 0 0.0082"/>
    </collision>
  </link>
  <joint name="joint_0" type="revolute">
    <axis xyz="0 0 1"/>
    <limit effort="0" lower="-0.47" upper="0.47" velocity="0"/>
    <parent link="base_link"/>
    <child link="link_0"/>
    <origin rpy="-0.08726646255 0 0" xyz="0 0.0435 -0.001542"/>
  </joint>
  <link name="link_1">
    <visual>
      <geometry>
        <mesh filename="meshes/link_1.0.STL"/>
      </geometry>
      <material name="black"/>
    </visual>
    <inertial>
      <mass value="0.06500000"/>
      <inertia ixx="1.5917e-8" ixy="6.0500e-19" ixz="-1.9640e-18" iyy="1.5037e-8" iyz="-4.3180e-14" izz="3.1035e-9"/>
      <origin xyz="0.00000000 -0.00003069 0.02699990"/>
    </inertial>
    <collision>
      <geometry>
        <box size="0.0196 0.0275 0.054"/>
      </geometry>
      <origin rpy="0 0 0" xyz="0 0 0.027"/>
    </collision>
  </link>
  <joint name="joint_1" type="revolute">
    <limit effort="0" lower="-0.196" upper="1.61" velocity="0"/>
    <axis xyz="0 1 0"/>
    <parent link="link_0"/>
    <child link="link_1"/>
    <origin xyz="0 0 0.0164"/>
  </joint>
  <link name="link_2">
    <visual>
      <geometry>
        <mesh filename="meshes/link_2.0.STL"/>
      </geometry>
      <material name="black"/>
    </visual>
    <inertial>
      <mass value="0.03550000"/>
      <inertia ixx="8.2002e-9" ixy="-4.2376e-11" ixz="-2.5993e-11" iyy="5.9630e-9" iyz="-5.2249e-10" izz="4.1430e-9"/>
      <origin xyz="-0.00014855 -0.00162236 0.02492425"/>
    </inertial>
    <collision>
      <geometry>
        <box size="0.0196 0.0275 0.0384"/>
      </geometry>
      <origin rpy="0 0 0" xyz="0 0 0.0192"/>
    </collision>
  </link>
  <joint name="joint_2" type="revolute">
    <axis xyz="0 1 0"/>
    <limit effort="0" lower="-0.174" upper="1.709" velocity="0"/>
    <parent link="link_1"/>
    <child link="link_2"/>
    <origin xyz="0 0 0.054"/>
  </joint>
  <link name="link_3">
    <visual>
      <geometry>
        <mesh filename="meshes/link_3.0.STL"/>
      </geometry>
      <material name="black"/>
    </visual>
    <inertial>
      <mass value="0.00480000"/>
      <inertia ixx="4.5827e-10" ixy="4.7378e-13" ixz="-1.2806e-11" iyy="2.2769e-10" iyz="2.9649e-12" izz="4.4562e-10"/>
      <origin xyz="-0.00030124 -0.00009704 0.00976183"/>
    </inertial>
    <collision>
      <geometry>
        <box size="0.0196 0.0275 0.0267"/>
      </geometry>
      <origin rpy="0 0 0" xyz="0 0 0.01335"/>
    </collision>
  </link>
  <joint name="joint_3" type="revolute">
    <axis xyz="0 1 0"/>
    <limit effort="0" lower="-0.227" upper="1.618" velocity="0"/>
    <parent link="link_2"/>
    <child link="link_3"/>
    <origin xyz="0 0 0.0384"/>
  </joint>
  <link name="link_3_tip">
    <visual>
      <geometry>
        <mesh filename="meshes/link_3.0_tip.STL"/>
      </geometry>
      <material name="white">
        <color rgba=".9 .9 .9 1"/>
      </material>
    </visual>
    <inertial>
      <mass value="0.00480000"/>
      <inertia ixx="7.6421e-10" ixy="-4.3347e-14" ixz="2.0810e-12" iyy="7.6149e-10" iyz="-4.4079e-13" izz="7.8814e-10"/>
      <origin xyz="-0.00003235 -0.00001387 -0.00235156"/>
    </inertial>
    <collision>
      <geometry>
        <sphere radius="0.012"/>
      </geometry>
    </collision>
  </link>
  <joint name="joint_3_tip" type="fixed">
    <parent link="link_3"/>
    <child link="link_3_tip"/>
    <origin rpy="0 0 0" xyz="0 0 0.0267"/>
  </joint>
  <link name="link_4">
    <visual>
      <geometry>
        <mesh filename="meshes/link_0.0.STL"/>
      </geometry>
      <material name="black"/>
    </visual>
    <inertial>
      <mass value="0.01190000"/>
      <inertia ixx="4.3968e-10" ixy="4.8612e-13" ixz="1.6056e-11" iyy="2.1654e-10" iyz="-5.7592e-12" izz="4.2916e-10"/>
      <origin xyz="-0.00047307 0.00024005 0.00596328"/>
    </inertial>
    <collision>
      <geometry>
        <box size="0.0196 0.0275 0.0164"/>
      </geometry>
      <origin rpy="0 0 0" xyz="0 0 0.0082"/>
    </collision>
  </link>
  <joint name="joint_4" type="revolute">
    <axis xyz="0 0 1"/>
    <limit effort="0" lower="-0.47" upper="0.47" velocity="0"/>
    <parent link="base_link"/>
    <child link="link_4"/>
    <origin rpy="0.0 0 0" xyz="0 0 0.0007"/>
  </joint>
  <link name="link_5">
    <visual>
      <geometry>
        <mesh filename="meshes/link_1.0.STL"/>
      </geometry>
      <material name="black"/>
    </visual>
    <inertial>
      <mass value="0.06500000"/>
      <inertia ixx="1.5917e-8" ixy="6.0500e-19" ixz="-1.9640e-18" iyy="1.5037e-8" iyz="-4.3180e-14" izz="3.1035e-9"/>
      <origin xyz="0.00000000 -0.00003069 0.02699990"/>
    </inertial>
    <collision>
      <geometry>
        <box size="0.0196 0.0275 0.054"/>
      </geometry>
      <origin rpy="0 0 0" xyz="0 0 0.027"/>
    </collision>
  </link>
  <joint name="joint_5" type="revolute">
    <limit effort="0" lower="-0.196" upper="1.61" velocity="0"/>
    <axis xyz="0 1 0"/>
    <parent link="link_4"/>
    <child link="link_5"/>
    <origin xyz="0 0 0.0164"/>
  </joint>
  <link name="link_6">
    <visual>
      <geometry>
        <mesh filename="meshes/link_2.0.STL"/>
      </geometry>
      <material name="black"/>
    </visual>
    <inertial>
      <mass value="0.03550000"/>
      <inertia ixx="8.2002e-9" ixy="-4.2376e-11" ixz="-2.5993e-11" iyy="5.9630e-9" iyz="-5.2249e-10" izz="4.1430e-9"/>
      <origin xyz="-0.00014855 -0.00162236 0.02492425"/>
    </inertial>
    <collision>
      <geometry>
        <box size="0.0196 0.0275 0.0384"/>
      </geometry>
      <origin rpy="0 0 0" xyz="0 0 0.0192"/>
    </collision>
  </link>
  <joint name="joint_6" type="revolute">
    <axis xyz="0 1 0"/>
    <limit effort="0" lower="-0.174" upper="1.709" velocity="0"/>
    <parent link="link_5"/>
    <child link="link_6"/>
    <origin xyz="0 0 0.054"/>
  </joint>
  <link name="link_7">
    <visual>
      <geometry>
        <mesh filename="meshes/link_3.0.STL"/>
      </geometry>
      <material name="black"/>
    </visual>
    <inertial>
      <mass value="0.00480000"/>
      <inertia ixx="4.5827e-10" ixy="4.7378e-13" ixz="-1.2806e-11" iyy="2.2769e-10" iyz="2.9649e-12" izz="4.4562e-10"/>
      <origin xyz="-0.00030124 -0.00009704 0.00976183"/>
    </inertial>
    <collision>
      <geometry>
        <box size="0.0196 0.0275 0.0267"/>
      </geometry>
      <origin rpy="0 0 0" xyz="0 0 0.01335"/>
    </collision>
  </link>
  <joint name="joint_7" type="revolute">
    <axis xyz="0 1 0"/>
    <limit effort="0" lower="-0.227" upper="1.618" velocity="0"/>
    <parent link="link_6"/>
    <child link="link_7"/>
    <origin xyz="0 0 0.0384"/>
  </joint>
  <link name="link_7_tip">
    <visual>
      <geometry>
        <mesh filename="meshes/link_3.0_tip.STL"/>
      </geometry>
      <material name="white">
        <color rgba=".9 .9 .9 1"/>
      </material>
    </visual>
    <inertial>
      <mass value="0.00480000"/>
      <inertia ixx="7.6421e-10" ixy="-4.3347e-14" ixz="2.0810e-12" iyy="7.6149e-10" iyz="-4.4079e-13" izz="7.8814e-10"/>
      <origin xyz="-0.00003235 -0.00001387 -0.00235156"/>
    </inertial>
    <collision>
      <geometry>
        <sphere radius="0.012"/>
      </geometry>
    </collision>
  </link>
  <joint name="joint_7_tip" type="fixed">
    <parent link="link_7"/>
    <child link="link_7_tip"/>
    <origin rpy="0 0 0" xyz="0 0 0.0267"/>
  </joint>
  <link name="link_8">
    <visual>
      <geometry>
        <mesh filename="meshes/link_0.0.STL"/>
      </geometry>
      <material name="black"/>
    </visual>
    <inertial>
      <mass value="0.01190000"/>
      <inertia ixx="4.3968e-10" ixy="4.8612e-13" ixz="1.6056e-11" iyy="2.1654e-10" iyz="-5.7592e-12" izz="4.2916e-10"/>
      <origin xyz="-0.00047307 0.00024005 0.00596328"/>
    </inertial>
    <collision>
      <geometry>
        <box size="0.0196 0.0275 0.0164"/>
      </geometry>
      <origin rpy="0 0 0" xyz="0 0 0.0082"/>
    </collision>
  </link>
  <joint name="joint_8" type="revolute">
    <axis xyz="0 0 1"/>
    <limit effort="0" lower="-0.47" upper="0.47" velocity="0"/>
    <parent link="base_link"/>
    <child link="link_8"/>
    <origin rpy="0.08726646255 0 0" xyz="0 -0.0435 -0.001542"/>
  </joint>
  <link name="link_9">
    <visual>
      <geometry>
        <mesh filename="meshes/link_1.0.STL"/>
      </geometry>
      <material name="black"/>
    </visual>
    <inertial>
      <mass value="0.06500000"/>
      <inertia ixx="1.5917e-8" ixy="6.0500e-19" ixz="-1.9640e-18" iyy="1.5037e-8" iyz="-4.3180e-14" izz="3.1035e-9"/>
      <origin xyz="0.00000000 -0.00003069 0.02699990"/>
    </inertial>
    <collision>
      <geometry>
        <box size="0.0196 0.0275 0.054"/>
      </geometry>
      <origin rpy="0 0 0" xyz="0 0 0.027"/>
    </collision>
  </link>
  <joint name="joint_9" type="revolute">
    <limit effort="0" lower="-0.196" upper="1.61" velocity="0"/>
    <axis xyz="0 1 0"/>
    <parent link="link_8"/>
    <child link="link_9"/>
    <origin xyz="0 0 0.0164"/>
  </joint>
  <link name="link_10">
    <visual>
      <geometry>
        <mesh filename="meshes/link_2.0.STL"/>
      </geometry>
      <material name="black"/>
    </visual>
    <inertial>
      <mass value="0.03550000"/>
      <inertia ixx="8.2002e-9" ixy="-4.2376e-11" ixz="-2.5993e-11" iyy="5.9630e-9" iyz="-5.2249e-10" izz="4.1430e-9"/>
      <origin xyz="-0.00014855 -0.00162236 0.02492425"/>
    </inertial>
    <collision>
      <geometry>
        <box size="0.0196 0.0275 0.0384"/>
      </geometry>
      <origin rpy="0 0 0" xyz="0 0 0.0192"/>
    </collision>
  </link>
  <joint name="joint_10" type="revolute">
    <axis xyz="0 1 0"/>
    <limit effort="0" lower="-0.174" upper="1.709" velocity="0"/>
    <parent link="link_9"/>
    <child link="link_10"/>
    <origin xyz="0 0 0.054"/>
  </joint>
  <link name="link_11">
    <visual>
      <geometry>
        <mesh filename="meshes/link_3.0.STL"/>
      </geometry>
      <material name="black"/>
    </visual>
    <inertial>
      <mass value="0.00480000"/>
      <inertia ixx="4.5827e-10" ixy="4.7378e-13" ixz="-1.2806e-11" iyy="2.2769e-10" iyz="2.9649e-12" izz="4.4562e-10"/>
      <origin xyz="-0.00030124 -0.00009704 0.00976183"/>
    </inertial>
    <collision>
      <geometry>
        <box size="0.0196 0.0275 0.0267"/>
      </geometry>
      <origin rpy="0 0 0" xyz="0 0 0.01335"/>
    </collision>
  </link>
  <joint name="joint_11" type="revolute">
    <axis xyz="0 1 0"/>
    <limit effort="0" lower="-0.227" upper="1.618" velocity="0"/>
    <parent link="link_10"/>
    <child link="link_11"/>
    <origin xyz="0 0 0.0384"/>
  </joint>
  <link name="link_11_tip">
    <visual>
      <geometry>
        <mesh filename="meshes/link_3.0_tip.STL"/>
      </geometry>
      <material name="white">
        <color rgba=".9 .9 .9 1"/>
      </material>
    </visual>
    <inertial>
      <mass value="0.00480000"/>
      <inertia ixx="7.6421e-10" ixy="-4.3347e-14" ixz="2.0810e-12" iyy="7.6149e-10" iyz="-4.4079e-13" izz="7.8814e-10"/>
      <origin xyz="-0.00003235 -0.00001387 -0.00235156"/>
    </inertial>
    <collision>
      <geometry>
        <sphere radius="0.012"/>
      </geometry>
    </collision>
  </link>
  <joint name="joint_11_tip" type="fixed">
    <parent link="link_11"/>
    <child link="link_11_tip"/>
    <origin rpy="0 0 0" xyz="0 0 0.0267"/>
  </joint>
  <!-- THUMB -->
  <link name="link_12">
    <visual>
      <geometry>
        <!-- RIGHT -->
        <mesh filename="meshes/link_12.0_right.STL"/>
        <!-- LEFT -->
        <!-- <mesh filename="package://allegro_hand_description/meshes/link_12.0_left.STL" /> -->
      </geometry>
      <material name="black">
        <color rgba=".2 .2 .2 1"/>
      </material>
    </visual>
    <inertial>
      <mass value="0.01760000"/>
      <inertia ixx="1.1262e-8" ixy="2.1880e-11" ixz="6.8010e-11" iyy="1.2881e-8" iyz="8.2109e-10" izz="8.6929e-9"/>
      <origin xyz="-0.01776469 0.00813654 0.01238897"/>
    </inertial>
    <collision>
      <geometry>
        <box size="0.0358 0.034 0.0455"/>
      </geometry>
      <!-- RIGHT -->
      <origin rpy="0 0 0" xyz="-0.0179 0.009 0.0145"/>
      <!-- LEFT -->
      <!-- <origin rpy="0 0 0" xyz="${-0.0358/2+0.0} ${-.018/2} ${.029/2}"/> -->
    </collision>
  </link>
  <joint name="joint_12" type="revolute">
    <axis xyz="-1 0 0"/>
    <limit effort="0" lower="0.263" upper="1.396" velocity="0"/>
    <parent link="base_link"/>
    <child link="link_12"/>
    <origin rpy="0 -1.65806278845 -1.5707963259" xyz="-0.0182 0.019333 -0.045987"/>
  </joint>
  <link name="link_13">
    <visual>
      <geometry>
        <mesh filename="meshes/link_13.0.STL"/>
      </geometry>
      <material name="black">
        <color rgba=".2 .2 .2 1"/>
      </material>
    </visual>
    <inertial>
      <mass value="0.01190000"/>
      <inertia ixx="4.2936e-10" ixy="4.6684e-13" ixz="1.5446e-11" iyy="2.1002e-10" iyz="-5.2752e-12" izz="4.2118e-10"/>
      <origin xyz="-0.00046728 0.00022601 0.00569165"/>
    </inertial>
    <collision>
      <geometry>
        <box size="0.0196 0.0275 0.0177"/>
      </geometry>
      <origin rpy="0 0 0" xyz="0 0 0.00885"/>
    </collision>
  </link>
  <joint name="joint_13" type="revolute">
    <axis xyz="0 0 1"/>
    <limit effort="0" lower="-0.105" upper="1.163" velocity="0"/>
    <parent link="link_12"/>
    <child link="link_13"/>
    <!-- RIGHT -->
    <origin xyz="-0.027 0.005 0.0399"/>
    <!-- LEFT -->
    <!-- <origin xyz="-0.027 -0.005 0.0399"/> -->
  </joint>
  <link name="link_14">
    <visual>
      <geometry>
        <mesh filename="meshes/link_14.0.STL"/>
      </geometry>
      <material name="black">
		  	</material>
    </visual>
    <inertial>
      <mass value="0.03800000"/>
      <inertia ixx="9.6753e-9" ixy="-2.1032e-12" ixz="2.5746e-11" iyy="7.7582e-9" iyz="2.7432e-10" izz="3.9455e-9"/>
      <origin xyz="-0.00013972 -0.00056652 0.01389734"/>
    </inertial>
    <collision>
      <geometry>
        <box size="0.0196 0.0275 0.0514"/>
      </geometry>
      <origin rpy="0 0 0" xyz="0 0 0.0257"/>
    </collision>
  </link>
  <joint name="joint_14" type="revolute">
    <axis xyz="0 1 0"/>
    <limit effort="0" lower="-0.189" upper="1.644" velocity="0"/>
    <parent link="link_13"/>
    <child link="link_14"/>
    <origin xyz="0 0 0.0177"/>
  </joint>
  <link name="link_15">
    <visual>
      <geometry>
        <mesh filename="meshes/link_15.0.STL"/>
      </geometry>
      <material name="black">
    	</material>
    </visual>
    <inertial>
      <mass value="0.03400000"/>
      <inertia ixx="3.6740e-9" ixy="-2.0110e-18" ixz="1.3500e-19" iyy="3.1686e-9" iyz="5.0312e-12" izz="1.7628e-9"/>
      <origin xyz="0.00000000 0.00006711 0.01212869"/>
    </inertial>
    <collision>
      <geometry>
        <box size="0.0196 0.0275 0.0423"/>
      </geometry>
      <origin rpy="0 0 0" xyz="0 0 0.02115"/>
    </collision>
  </link>
  <joint name="joint_15" type="revolute">
    <axis xyz="0 1 0"/>
    <limit effort="0" lower="-0.162" upper="1.719" velocity="0"/>
    <parent link="link_14"/>
    <child link="link_15"/>
    <origin xyz="0 0 0.0514"/>
  </joint>
  <link name="link_15_tip">
    <visual>
      <geometry>
        <mesh filename="meshes/link_15.0_tip.STL"/>
      </geometry>
      <material name="white">
        <color rgba=".9 .9 .9 1"/>
      </material>
    </visual>
    <inertial>
      <mass value="0.00480000"/>
      <inertia ixx="7.6421e-10" ixy="-4.3347e-14" ixz="2.0810e-12" iyy="7.6149e-10" iyz="-4.4079e-13" izz="7.8814e-10"/>
      <origin xyz="-0.00003235 -0.00001387 -0.00235156"/>
    </inertial>
    <collision>
      <geometry>
        <sphere radius="0.012"/>
      </geometry>
      <origin rpy="0 0 0" xyz="0 0 0"/>
    </collision>
  </link>
  <joint name="joint_15_tip" type="fixed">
    <parent link="link_15"/>
    <child link="link_15_tip"/>
    <origin rpy="0 0 0" xyz="0 0 0.0423"/>
    <!--0.0267000000000005-->
  </joint>
  <!--
<xacro:thumb_left 
	finger_num=			"3" 
	offset_origin_x=	"-0.0182"	
	offset_origin_y=	"-0.019333" 
	offset_origin_z=	"-0.045987" 
	
	
	finger_angle_r=		"${90*DEG2RAD}"
	finger_angle_p=		"-${95*DEG2RAD}"	
	finger_angle_y=		"${90*DEG2RAD}"
/>
-->
  <!-- ============================================================================= -->
  <!-- ============================================================================= -->
  <!-- ============================================================================= -->
  <!-- THUMB MACRO -->
  <!-- END THUMB MACRO -->
  <!-- THREE FINGER MACRO -->
  <!-- [[END]] THREE FINGER MACRO -->
</robot>
